<sdf version='1.11'>
  <model name='mycobot_280'>
    <joint name='virtual_joint' type='fixed'>
      <pose relative_to='__model__'>0 0 0 0 0 0</pose>
      <parent>world</parent>
      <child>base_link</child>
    </joint>
    <link name='base_link'>
      <pose relative_to='virtual_joint'>0 0 0 0 0 0</pose>
      <inertial>
        <pose>0 0 0 0 0 0</pose>
        <mass>0.45000000000000001</mass>
        <inertia>
          <ixx>0.00093199999999999999</ixx>
          <ixy>0</ixy>
          <ixz>0</ixz>
          <iyy>0.0010150000000000001</iyy>
          <iyz>0</iyz>
          <izz>0.001694</izz>
        </inertia>
      </inertial>
      <collision name='base_link_collision'>
        <pose>0 0 -0.029999999999999999 0 0 1.5707963267948959</pose>
        <geometry>
          <mesh>
            <scale>1 1 1</scale>
            <uri>file:///home/anel/GitHub/pick_and_place_ros/anel_ws/install/mycobot_ros2_description/share/mycobot_ros2_description/mesh/base_link.dae</uri>
          </mesh>
        </geometry>
      </collision>
      <collision name='base_link_fixed_joint_lump__link1_collision_1'>
        <pose>0 0 0 0 0 -1.5707963267948959</pose>
        <geometry>
          <mesh>
            <scale>1 1 1</scale>
            <uri>file:///home/anel/GitHub/pick_and_place_ros/anel_ws/install/mycobot_ros2_description/share/mycobot_ros2_description/mesh/link1.dae</uri>
          </mesh>
        </geometry>
      </collision>
      <visual name='base_link_visual'>
        <pose>0 0 -0.029999999999999999 0 0 1.5707963267948959</pose>
        <geometry>
          <mesh>
            <scale>1 1 1</scale>
            <uri>file:///home/anel/GitHub/pick_and_place_ros/anel_ws/install/mycobot_ros2_description/share/mycobot_ros2_description/mesh/base_link.dae</uri>
          </mesh>
        </geometry>
      </visual>
      <visual name='base_link_fixed_joint_lump__link1_visual_1'>
        <pose>0 0 0 0 0 -1.5707963267948959</pose>
        <geometry>
          <mesh>
            <scale>1 1 1</scale>
            <uri>file:///home/anel/GitHub/pick_and_place_ros/anel_ws/install/mycobot_ros2_description/share/mycobot_ros2_description/mesh/link1.dae</uri>
          </mesh>
        </geometry>
      </visual>
    </link>
    <joint name='link1_to_link2' type='revolute'>
      <pose relative_to='base_link'>0 0 0.13156000000000001 0 0 1.5707963267948959</pose>
      <parent>base_link</parent>
      <child>link2</child>
      <axis>
        <xyz>0 0 1</xyz>
        <limit>
          <lower>-2.8797929999999998</lower>
          <upper>2.8797929999999998</upper>
          <effort>5</effort>
          <velocity>2.7925270000000002</velocity>
        </limit>
        <dynamics>
          <damping>0.050000000000000003</damping>
          <friction>0.050000000000000003</friction>
          <spring_reference>0</spring_reference>
          <spring_stiffness>0</spring_stiffness>
        </dynamics>
      </axis>
    </joint>
    <link name='link2'>
      <pose relative_to='link1_to_link2'>0 0 0 0 0 0</pose>
      <inertial>
        <pose>0 0 0 0 0 0</pose>
        <mass>0.19</mass>
        <inertia>
          <ixx>0.00014799999999999999</ixx>
          <ixy>0</ixy>
          <ixz>0</ixz>
          <iyy>0.00014799999999999999</iyy>
          <iyz>0</iyz>
          <izz>9.6000000000000002e-05</izz>
        </inertia>
      </inertial>
      <collision name='link2_collision'>
        <pose>0 0 -0.06096 0 0 -1.5707963267948959</pose>
        <geometry>
          <mesh>
            <scale>1 1 1</scale>
            <uri>file:///home/anel/GitHub/pick_and_place_ros/anel_ws/install/mycobot_ros2_description/share/mycobot_ros2_description/mesh/link2.dae</uri>
          </mesh>
        </geometry>
      </collision>
      <visual name='link2_visual'>
        <pose>0 0 -0.06096 0 0 -1.5707963267948959</pose>
        <geometry>
          <mesh>
            <scale>1 1 1</scale>
            <uri>file:///home/anel/GitHub/pick_and_place_ros/anel_ws/install/mycobot_ros2_description/share/mycobot_ros2_description/mesh/link2.dae</uri>
          </mesh>
        </geometry>
      </visual>
    </link>
    <joint name='link2_to_link3' type='revolute'>
      <pose relative_to='link2'>0 0 -0.001 1.5707963267948957 1.5707963267948966 0</pose>
      <parent>link2</parent>
      <child>link3</child>
      <axis>
        <xyz>0 0 1</xyz>
        <limit>
          <lower>-2.8797929999999998</lower>
          <upper>2.8797929999999998</upper>
          <effort>5</effort>
          <velocity>2.7925270000000002</velocity>
        </limit>
        <dynamics>
          <damping>0.20499999999999999</damping>
          <friction>0.14999999999999999</friction>
          <spring_reference>0</spring_reference>
          <spring_stiffness>0</spring_stiffness>
        </dynamics>
      </axis>
    </joint>
    <link name='link3'>
      <pose relative_to='link2_to_link3'>0 0 0 0 0 0</pose>
      <inertial>
        <pose>0 0 0 0 0 0</pose>
        <mass>0.16</mass>
        <inertia>
          <ixx>0.00014799999999999999</ixx>
          <ixy>0</ixy>
          <ixz>0</ixz>
          <iyy>0.00014799999999999999</iyy>
          <iyz>0</iyz>
          <izz>9.6000000000000002e-05</izz>
        </inertia>
      </inertial>
      <collision name='link3_collision'>
        <pose>0 0 0.032559999999999999 0 -1.5707963267948966 0</pose>
        <geometry>
          <mesh>
            <scale>1 1 1</scale>
            <uri>file:///home/anel/GitHub/pick_and_place_ros/anel_ws/install/mycobot_ros2_description/share/mycobot_ros2_description/mesh/link3.dae</uri>
          </mesh>
        </geometry>
      </collision>
      <visual name='link3_visual'>
        <pose>0 0 0.032559999999999999 0 -1.5707963267948966 0</pose>
        <geometry>
          <mesh>
            <scale>1 1 1</scale>
            <uri>file:///home/anel/GitHub/pick_and_place_ros/anel_ws/install/mycobot_ros2_description/share/mycobot_ros2_description/mesh/link3.dae</uri>
          </mesh>
        </geometry>
      </visual>
    </link>
    <joint name='link3_to_link4' type='revolute'>
      <pose relative_to='link3'>-0.1104 0 0 0 0 0</pose>
      <parent>link3</parent>
      <child>link4</child>
      <axis>
        <xyz>0 0 1</xyz>
        <limit>
          <lower>-2.8797929999999998</lower>
          <upper>2.8797929999999998</upper>
          <effort>5</effort>
          <velocity>2.7925270000000002</velocity>
        </limit>
        <dynamics>
          <damping>0.20999999999999999</damping>
          <friction>0.40999999999999998</friction>
          <spring_reference>0</spring_reference>
          <spring_stiffness>0</spring_stiffness>
        </dynamics>
      </axis>
    </joint>
    <link name='link4'>
      <pose relative_to='link3_to_link4'>0 0 0 0 0 0</pose>
      <inertial>
        <pose>0 0 0 0 0 0</pose>
        <mass>0.124</mass>
        <inertia>
          <ixx>0.000103</ixx>
          <ixy>0</ixy>
          <ixz>0</ixz>
          <iyy>0.000103</iyy>
          <iyz>0</iyz>
          <izz>9.6000000000000002e-05</izz>
        </inertia>
      </inertial>
      <collision name='link4_collision'>
        <pose>0 0 0.03056 0 -1.5707963267948966 0</pose>
        <geometry>
          <mesh>
            <scale>1 1 1</scale>
            <uri>file:///home/anel/GitHub/pick_and_place_ros/anel_ws/install/mycobot_ros2_description/share/mycobot_ros2_description/mesh/link4.dae</uri>
          </mesh>
        </geometry>
      </collision>
      <visual name='link4_visual'>
        <pose>0 0 0.03056 0 -1.5707963267948966 0</pose>
        <geometry>
          <mesh>
            <scale>1 1 1</scale>
            <uri>file:///home/anel/GitHub/pick_and_place_ros/anel_ws/install/mycobot_ros2_description/share/mycobot_ros2_description/mesh/link4.dae</uri>
          </mesh>
        </geometry>
      </visual>
    </link>
    <joint name='link4_to_link5' type='revolute'>
      <pose relative_to='link4'>-0.096000000000000002 0 0.06062 0 0 -1.5707963267948959</pose>
      <parent>link4</parent>
      <child>link5</child>
      <axis>
        <xyz>0 0 1</xyz>
        <limit>
          <lower>-2.8797929999999998</lower>
          <upper>2.8797929999999998</upper>
          <effort>5</effort>
          <velocity>2.7925270000000002</velocity>
        </limit>
        <dynamics>
          <damping>0.10000000000000001</damping>
          <friction>0.20000000000000001</friction>
          <spring_reference>0</spring_reference>
          <spring_stiffness>0</spring_stiffness>
        </dynamics>
      </axis>
    </joint>
    <link name='link5'>
      <pose relative_to='link4_to_link5'>0 0 0 0 0 0</pose>
      <inertial>
        <pose>0 0 0 0 0 0</pose>
        <mass>0.11</mass>
        <inertia>
          <ixx>0.000103</ixx>
          <ixy>0</ixy>
          <ixz>0</ixz>
          <iyy>0.000103</iyy>
          <iyz>0</iyz>
          <izz>9.6000000000000002e-05</izz>
        </inertia>
      </inertial>
      <collision name='link5_collision'>
        <pose>0 0 -0.03356 -1.5707963267948959 0 0</pose>
        <geometry>
          <mesh>
            <scale>1 1 1</scale>
            <uri>file:///home/anel/GitHub/pick_and_place_ros/anel_ws/install/mycobot_ros2_description/share/mycobot_ros2_description/mesh/link5.dae</uri>
          </mesh>
        </geometry>
      </collision>
      <visual name='link5_visual'>
        <pose>0 0 -0.03356 -1.5707963267948959 0 0</pose>
        <geometry>
          <mesh>
            <scale>1 1 1</scale>
            <uri>file:///home/anel/GitHub/pick_and_place_ros/anel_ws/install/mycobot_ros2_description/share/mycobot_ros2_description/mesh/link5.dae</uri>
          </mesh>
        </geometry>
      </visual>
    </link>
    <joint name='link5_to_link6' type='revolute'>
      <pose relative_to='link5'>0 -0.073179999999999995 0 1.5707963267948957 -1.5707963267948966 0</pose>
      <parent>link5</parent>
      <child>link6</child>
      <axis>
        <xyz>0 0 1</xyz>
        <limit>
          <lower>-2.8797929999999998</lower>
          <upper>2.8797929999999998</upper>
          <effort>5</effort>
          <velocity>2.7925270000000002</velocity>
        </limit>
        <dynamics>
          <damping>0.01</damping>
          <friction>0.0050000000000000001</friction>
          <spring_reference>0</spring_reference>
          <spring_stiffness>0</spring_stiffness>
        </dynamics>
      </axis>
    </joint>
    <link name='link6'>
      <pose relative_to='link5_to_link6'>0 0 0 0 0 0</pose>
      <inertial>
        <pose>0 0 0 0 0 0</pose>
        <mass>0.073899999999999993</mass>
        <inertia>
          <ixx>6.6489999999999995e-05</ixx>
          <ixy>0</ixy>
          <ixz>0</ixz>
          <iyy>6.6489999999999995e-05</iyy>
          <iyz>0</iyz>
          <izz>9.6000000000000002e-05</izz>
        </inertia>
      </inertial>
      <collision name='link6_collision'>
        <pose>0 0 -0.037999999999999999 0 0 0</pose>
        <geometry>
          <mesh>
            <scale>1 1 1</scale>
            <uri>file:///home/anel/GitHub/pick_and_place_ros/anel_ws/install/mycobot_ros2_description/share/mycobot_ros2_description/mesh/link6.dae</uri>
          </mesh>
        </geometry>
      </collision>
      <visual name='link6_visual'>
        <pose>0 0 -0.037999999999999999 0 0 0</pose>
        <geometry>
          <mesh>
            <scale>1 1 1</scale>
            <uri>file:///home/anel/GitHub/pick_and_place_ros/anel_ws/install/mycobot_ros2_description/share/mycobot_ros2_description/mesh/link6.dae</uri>
          </mesh>
        </geometry>
      </visual>
    </link>
    <plugin name='ignition::gazebo::systems::JointStatePublisher' filename='ignition-gazebo-joint-state-publisher-system'>
      <topic>joint_states</topic>
    </plugin>
    <plugin name='ignition::gazebo::systems::JointPositionController' filename='ignition-gazebo-joint-position-controller-system'>
      <joint_name>link1_to_link2</joint_name>
    </plugin>
    <plugin name='ignition::gazebo::systems::JointPositionController' filename='ignition-gazebo-joint-position-controller-system'>
      <joint_name>link2_to_link3</joint_name>
    </plugin>
    <plugin name='ignition::gazebo::systems::JointPositionController' filename='ignition-gazebo-joint-position-controller-system'>
      <joint_name>link3_to_link4</joint_name>
    </plugin>
    <plugin name='ignition::gazebo::systems::JointPositionController' filename='ignition-gazebo-joint-position-controller-system'>
      <joint_name>link4_to_link5</joint_name>
    </plugin>
    <plugin name='ignition::gazebo::systems::JointPositionController' filename='ignition-gazebo-joint-position-controller-system'>
      <joint_name>link5_to_link6</joint_name>
    </plugin>
    <plugin name='ignition::gazebo::systems::JointPositionController' filename='ignition-gazebo-joint-position-controller-system'>
      <joint_name>link6_to_link6flange</joint_name>
    </plugin>
    <plugin name='ignition::gazebo::systems::JointPositionController' filename='ignition-gazebo-joint-position-controller-system'>
      <joint_name>gripper_controller</joint_name>
    </plugin>
    <plugin name='ignition::gazebo::systems::JointPositionController' filename='ignition-gazebo-joint-position-controller-system'>
      <joint_name>gripper_base_to_gripper_left2</joint_name>
    </plugin>
    <plugin name='ignition::gazebo::systems::JointPositionController' filename='ignition-gazebo-joint-position-controller-system'>
      <joint_name>gripper_left3_to_gripper_left1</joint_name>
    </plugin>
    <plugin name='ignition::gazebo::systems::JointPositionController' filename='ignition-gazebo-joint-position-controller-system'>
      <joint_name>gripper_base_to_gripper_right3</joint_name>
    </plugin>
    <plugin name='ignition::gazebo::systems::JointPositionController' filename='ignition-gazebo-joint-position-controller-system'>
      <joint_name>gripper_base_to_gripper_right2</joint_name>
    </plugin>
    <plugin name='ignition::gazebo::systems::JointPositionController' filename='ignition-gazebo-joint-position-controller-system'>
      <joint_name>gripper_right3_to_gripper_right1</joint_name>
    </plugin>
    <frame name='base_link_to_link1' attached_to='base_link'>
      <pose>0 0 0 0 0 0</pose>
    </frame>
    <frame name='link1' attached_to='base_link_to_link1'>
      <pose>0 0 0 0 0 0</pose>
    </frame>
  </model>
</sdf>
