<?xml version="1.0"?>
<robot  xmlns:xacro="http://www.ros.org/wiki/xacro" name="mycobot_320pi" >

  <xacro:property name="width" value=".2" />
  <!-- Add internal gazebo visualisation -->
  <xacro:include filename="$(find mycobot_description)/xacro/macro.gazebo_internal_config.xacro" />
  <!-- Add ros2_control tag to access and control robot interfaces -->
  <xacro:include filename="$(find mycobot_description)/xacro/macro.gazebo_config_ros2_control.xacro" />

  <xacro:macro name="mycobot_320pi" params="namespace">
    <!-- Base -->
    <link name="base_link">
      <!-- Inertial parameters are from https://github.com/automaticaddison/mycobot_ros2/blob/main/mycobot_gazebo/urdf/mycobot_280_gazebo.urdf.xacro-->
      <inertial>
        <origin xyz="0 0 0.0" rpy="0 0 0"/>
        <mass value="0.33"/>
        <inertia
          ixx="0.000784" ixy="0.0" ixz="0.0"
          iyy="0.000867" iyz="0.0"
          izz="0.001598"/>
      </inertial>
      <visual>
        <origin xyz = "0.0 0 0 " rpy = " 0 0 3.1415926"/>
        <geometry>
          <!--- 0.0 0 -0.04  1.5708 3.14159-->
          <!-- <mesh filename="file:///$(find mycobot_description)/mesh/base_link.dae" scale="0.001 0.001 0.001" /> -->
          <mesh filename="file:///$(find mycobot_description)/mesh/base_link.dae" />
        </geometry>
      </visual>
      <collision>
        <origin xyz = "0.0 0 0 " rpy = " 0 0 3.1415926"/> <!-- doosan_pkg robot doesn't have this-->
        <geometry>
          <!--- 0.0 0 -0.04  1.5708 3.14159-->
          <mesh filename="file:///$(find mycobot_description)/mesh/base_link.dae"/>
        </geometry>
      </collision>
    </link>

    <!-- Link 1 -->
    <link name="link1">
      <inertial>
        <origin xyz="0 0 0.0" rpy="0 0 0"/>
        <mass value="0.12"/>
        <inertia
          ixx="0.000148" ixy="0.0" ixz="0.0"
          iyy="0.000148" iyz="0.0"
          izz="0.000096"/>
      </inertial>
      <visual>
        <origin xyz = "0.115 -0.172 -0.086 " rpy = " 0 0 3.1415926"/>
        <geometry>
          <mesh filename="file:///$(find mycobot_description)/mesh/link1.dae"/>
        </geometry>
      </visual>
      <collision>
        <origin xyz = "0.115 -0.172 -0.09 " rpy = " 0 0 3.1415926"/>
        <geometry>
          <mesh filename="file:///$(find mycobot_description)/mesh/link1.dae"/>
        </geometry>
      </collision>
    </link>

    <!-- Link 2 -->
    <link name="link2">
      <inertial>
        <origin xyz="0 0 0.0" rpy="0 0 0"/>
        <mass value="0.19"/>
        <inertia
          ixx="0.000148" ixy="0.0" ixz="0.0"
          iyy="0.000148" iyz="0.0"
          izz="0.000096"/>
      </inertial>
      <visual>
        <origin xyz = "-0.075 -0.115 -0.022 " rpy = " 1.5708 0 1.5708"/>
        <geometry>
          <mesh filename="file:///$(find mycobot_description)/mesh/link2.dae"/>
        </geometry>
      </visual>
      <collision>
        <origin xyz = "-0.075 -0.115 -0.022 " rpy = " 1.5708 0 1.5708"/>
        <geometry>
          <mesh filename="file:///$(find mycobot_description)/mesh/link2.dae"/>
        </geometry>
      </collision>
    </link>

  <!-- Link 3 -->
    <link name="link3">
      <inertial>
        <origin xyz="0 0 0.0" rpy="0 0 0"/>
          <mass value="0.16"/>
        <inertia
          ixx="0.000148" ixy="0.0" ixz="0.0"
          iyy="0.000148" iyz="0.0"
          izz="0.000096"/>
      </inertial>
      <visual>
        <origin xyz = "-0.22 -0.115 0.142 " rpy = " 1.5708 0 1.5708"/>
        <geometry>
          <mesh filename="file:///$(find mycobot_description)/mesh/link3.dae"/>
        </geometry>
      </visual>
      <collision>
        <origin xyz = "-0.22 -0.115 0.142 " rpy = " 1.5708 0 1.5708"/>
        <geometry>
          <mesh filename="file:///$(find mycobot_description)/mesh/link3.dae"/>
        </geometry>
      </collision>
    </link>

  <!-- Link 4 -->
    <link name="link4">
      <inertial>
        <origin xyz="0 0 0.0" rpy="0 0 0"/>
      <mass value="0.124"/>
      <inertia
        ixx="0.000103" ixy="0.0" ixz="0.0"
        iyy="0.000103" iyz="0.0"
        izz="0.000096"/>
      </inertial>
      <visual>
        <origin xyz = "-0.115 0.338 -0.1435" rpy = " 1.5708 0 0"/>
        <geometry>
          <mesh filename="file:///$(find mycobot_description)/mesh/link4.dae"/>
        </geometry>
      </visual>
      <collision>
        <origin xyz = "-0.115 0.338 -0.1435 " rpy = " 1.5708 0 0"/>
        <geometry>
          <mesh filename="file:///$(find mycobot_description)/mesh/link4.dae"/>
        </geometry>
      </collision>
    </link>

  <!-- Link 5 -->
    <link name="link5">
      <inertial>
        <origin xyz="0 0 0.0" rpy="0 0 0"/>
          <mass value="0.11"/>
        <inertia
          ixx="0.000103" ixy="0.0" ixz="0.0"
          iyy="0.000103" iyz="0.0"
          izz="0.000096"/>
      </inertial>
      <visual>
        <origin xyz = "-0.1149 -0.0322  -0.482 " rpy = " 0  0 0"/>
        <geometry>
          <mesh filename="file:///$(find mycobot_description)/mesh/link5.dae"/>
        </geometry>
      </visual>
      <collision>
        <origin xyz = "-0.1149 -0.0322  -0.482 " rpy = " 0  0 0"/>
        <geometry>
          <mesh filename="file:///$(find mycobot_description)/mesh/link5.dae"/>
        </geometry>
      </collision>
    </link>

  <!-- Link 6 -->
    <link name="link6">
      <inertial>
        <origin xyz="0 0 0.0" rpy="0 0 0"/>
          <mass value="0.0739"/>
        <inertia
          ixx="0.00006649" ixy="0.0" ixz="0.0"
          iyy="0.00006649" iyz="0.0"
          izz="0.000096"/>
      </inertial>
      <visual>
        <origin xyz = "-0.11478 0.433 -0.15 " rpy = " 1.5708 0 0"/>
        <geometry>
          <mesh filename="file:///$(find mycobot_description)/mesh/link6.dae"/>
        </geometry>
      </visual>
      <collision>
        <origin xyz = "-0.11478 0.433 -0.15 " rpy = " 1.5708 0 0"/>
        <geometry>
          <mesh filename="file:///$(find mycobot_description)/mesh/link6.dae"/>
        </geometry>
      </collision>
    </link>


    <!-- Joints -->
    <joint name="joint2_to_joint1" type="revolute">
      <axis xyz="0 0 1"/>
      <limit effort = "1000.0" lower = "-2.96" upper = "2.96" velocity = "0"/>
      <parent link="base_link"/>
      <child link="link1"/>
      <origin xyz= "0 0 0.162" rpy = "0 0 0"/> 
      <dynamics damping="0.05" friction="0.05" /> <!-- From https://github.com/automaticaddison/mycobot_ros2/blob/main/mycobot_gazebo/urdf/mycobot_280_gazebo.urdf.xacro#L383C29-L383C51-->
    </joint>


    <joint name="joint3_to_joint2" type="revolute">
      <axis xyz="0 0 1"/>
      <limit effort = "1000.0" lower = "-2.79" upper = "2.79" velocity = "0"/>
      <parent link="link1"/>
      <child link="link2"/>
      <origin xyz= "0 0 0" rpy = "0 -1.5708 1.5708"/>
      <dynamics damping="0.0" friction="0.0"/>
    </joint>


    <joint name="joint4_to_joint3" type="revolute">
      <axis xyz=" 0 0 1"/>
      <limit effort = "1000.0" lower = "-2.79" upper = "2.79" velocity = "0"/>
      <parent link="link2"/>
      <child link="link3"/>
      <origin xyz= "0.13635 0 0   " rpy = "0 0 0"/>
      <dynamics damping="0.0" friction="0.0"/>
    </joint>


    <joint name="joint5_to_joint4" type="revolute">
      <axis xyz=" 0 0 1"/>
      <limit effort = "1000.0" lower = "-2.79" upper = "2.79" velocity = "0"/>
      <parent link="link3"/>
      <child link="link4"/>
      <!-- <origin xyz = "0.12 0 0.09 " rpy = " 0 0 1.57080"/> -->
      <origin xyz = "0.1205 0 0.082 " rpy = " 0 0 1.57080"/>
      <dynamics damping="0.0" friction="0.0"/>
    </joint>


    <joint name="joint6_to_joint5" type="revolute">
      <axis xyz="0 0 1"/>
      <limit effort = "1000.0" lower = "-2.96" upper = "2.96" velocity = "0"/>
      <parent link="link4"/>
      <child link="link5"/>
      <origin xyz= "0 -0.084 0" rpy = "1.5708 0 0"/>
      <dynamics damping="0.0" friction="0.0"/>
    </joint>


    <joint name="joint6output_to_joint6" type="revolute">
      <axis xyz="0 0 1"/>
      <limit effort = "1000.0" lower = "-3.05" upper = "3.05" velocity = "0"/>
      <parent link="link5"/>
      <child link="link6"/>
      <origin xyz= "0 0.06635 0" rpy = "-1.5708 0 0"/>
      <dynamics damping="0.0" friction="0.0"/>
    </joint>
  </xacro:macro>
</robot>
